Workbook

Sheet Raw Data
A1: Row ID | B1: Order ID | C1: Order Date | D1: Ship Date | E1: Ship Mode | F1: Customer ID | G1: Customer Name | H1: Segment | I1: Country | J1: City | K1: State | L1: Postal Code | M1: Region | N1: Product ID | O1: Category | P1: Sub-Category | Q1: Product Name | R1: Sales | S1: Quantity | T1: Discount | U1: Profit | V1: Order Date Fixed
A2: 1 | B2: CA-2016-152156 | C2: 42593 | D2: 42685 | E2: Second Class | F2: CG-12520 | G2: Claire Gute | H2: Consumer | I2: United States | J2: Henderson | K2: Kentucky | L2: 42420 | M2: South | N2: FUR-BO-10001798 | O2: Furniture | P2: Bookcases | Q2: Bush Somerset Collection Bookcase | R2: 261.96 | S2: 2 | T2: 0 | U2: 41.9136 | V2: =IF(ISNUMBER(SalesData[[#This Row],[Order Date]]),DATE(YEAR(SalesData[[#This Row],[Order Date]]),DAY(SalesData[[#This Row],[Order Date]]),MONTH(SalesData[[#This Row],[Order Date]])),DATE(VALUE(RIGHT(SalesData[[#This Row],[Order Date]],4)),VALUE(LEFT(SalesData[[#This Row],[Order Date]],FIND("/",SalesData[[#This Row],[Order Date]])-1)),VALUE(MID(SalesData[[#This Row],[Order Date]],FIND("/",SalesData[[#This Row],[Order Date]])+1,FIND("/",SalesData[[#This Row],[Order Date]],FIND("/",SalesData[[#This Row],[Order Date]])+1)-FIND("/",SalesData[[#This Row],[Order Date]])-1)))) -> 42682
A3: 2 | B3: CA-2016-152156 | C3: 42593 | D3: 42685 | E3: Second Class | F3: CG-12520 | G3: Claire Gute | H3: Consumer | I3: United States | J3: Henderson | K3: Kentucky | L3: 42420 | M3: South | N3: FUR-CH-10000454 | O3: Furniture | P3: Chairs | Q3: Hon Deluxe Fabric Upholstered Stacking Chairs, Rounded Back | R3: 731.94 | S3: 3 | T3: 0 | U3: 219.582 | V3: =IF(ISNUMBER(SalesData[[#This Row],[Order Date]]),DATE(YEAR(SalesData[[#This Row],[Order Date]]),DAY(SalesData[[#This Row],[Order Date]]),MONTH(SalesData[[#This Row],[Order Date]])),DATE(VALUE(RIGHT(SalesData[[#This Row],[Order Date]],4)),VALUE(LEFT(SalesData[[#This Row],[Order Date]],FIND("/",SalesData[[#This Row],[Order Date]])-1)),VALUE(MID(SalesData[[#This Row],[Order Date]],FIND("/",SalesData[[#This Row],[Order Date]])+1,FIND("/",SalesData[[#This Row],[Order Date]],FIND("/",SalesData[[#This Row],[Order Date]])+1)-FIND("/",SalesData[[#This Row],[Order Date]])-1)))) -> 42682
A4: 3 | B4: CA-2016-138688 | C4: 42710 | D4: 6/16/2016 | E4: Second Class | F4: DV-13045 | G4: Darrin Van Huff | H4: Corporate | I4: United States | J4: Los Angeles | K4: California | L4: 90036 | M4: West | N4: OFF-LA-10000240 | O4: Office Supplies | P4: Labels | Q4: Self-Adhesive Address Labels for Typewriters by Universal | R4: 14.62 | S4: 2 | T4: 0 | U4: 6.8714 | V4: =IF(ISNUMBER(SalesData[[#This Row],[Order Date]]),DATE(YEAR(SalesData[[#This Row],[Order Date]]),DAY(SalesData[[#This Row],[Order Date]]),MONTH(SalesData[[#This Row],[Order Date]])),DATE(VALUE(RIGHT(SalesData[[#This Row],[Order Date]],4)),VALUE(LEFT(SalesData[[#This Row],[Order Date]],FIND("/",SalesData[[#This Row],[Order Date]])-1)),VALUE(MID(SalesData[[#This Row],[Order Date]],FIND("/",SalesData[[#This Row],[Order Date]])+1,FIND("/",SalesData[[#This Row],[Order Date]],FIND("/",SalesData[[#This Row],[Order Date]])+1)-FIND("/",SalesData[[#This Row],[Order Date]])-1)))) -> 42533
A5: 4 | B5: US-2015-108966 | C5: 42318 | D5: 10/18/2015 | E5: Standard Class | F5: SO-20335 | G5: Sean O'Donnell | H5: Consumer | I5: United States | J5: Fort Lauderdale | K5: Florida | L5: 33311 | M5: South | N5: FUR-TA-10000577 | O5: Furniture | P5: Tables | Q5: Bretford CR4500 Series Slim Rectangular Table | R5: 957.5775 | S5: 5 | T5: 0.45 | U5: -383.031 | V5: =IF(ISNUMBER(SalesData[[#This Row],[Order Date]]),DATE(YEAR(SalesData[[#This Row],[Order Date]]),DAY(SalesData[[#This Row],[Order Date]]),MONTH(SalesData[[#This Row],[Order Date]])),DATE(VALUE(RIGHT(SalesData[[#This Row],[Order Date]],4)),VALUE(LEFT(SalesData[[#This Row],[Order Date]],FIND("/",SalesData[[#This Row],[Order Date]])-1)),VALUE(MID(SalesData[[#This Row],[Order Date]],FIND("/",SalesData[[#This Row],[Order Date]])+1,FIND("/",SalesData[[#This Row],[Order Date]],FIND("/",SalesData[[#This Row],[Order Date]])+1)-FIND("/",SalesData[[#This Row],[Order Date]])-1)))) -> 42288
A6: 5 | B6: US-2015-108966 | C6: 42318 | D6: 10/18/2015 | E6: Standard Class | F6: SO-20335 | G6: Sean O'Donnell | H6: Consumer | I6: United States | J6: Fort Lauderdale | K6: Florida | L6: 33311 | M6: South | N6: OFF-ST-10000760 | O6: Office Supplies | P6: Storage | Q6: Eldon Fold 'N Roll Cart System | R6: 22.368 | S6: 2 | T6: 0.2 | U6: 2.5164 | V6: =IF(ISNUMBER(SalesData[[#This Row],[Order Date]]),DATE(YEAR(SalesData[[#This Row],[Order Date]]),DAY(SalesData[[#This Row],[Order Date]]),MONTH(SalesData[[#This Row],[Order Date]])),DATE(VALUE(RIGHT(SalesData[[#This Row],[Order Date]],4)),VALUE(LEFT(SalesData[[#This Row],[Order Date]],FIND("/",SalesData[[#This Row],[Order Date]])-1)),VALUE(MID(SalesData[[#This Row],[Order Date]],FIND("/",SalesData[[#This Row],[Order Date]])+1,FIND("/",SalesData[[#This Row],[Order Date]],FIND("/",SalesData[[#This Row],[Order Date]])+1)-FIND("/",SalesData[[#This Row],[Order Date]])-1)))) -> 42288
A7: 6 | B7: CA-2014-115812 | C7: 41888 | D7: 6/14/2014 | E7: Standard Class | F7: BH-11710 | G7: Brosina Hoffman | H7: Consumer | I7: United States | J7: Los Angeles | K7: California | L7: 90032 | M7: West | N7: FUR-FU-10001487 | O7: Furniture | P7: Furnishings | Q7: Eldon Expressions Wood and Plastic Desk Accessories, Cherry Wood | R7: 48.86 | S7: 7 | T7: 0 | U7: 14.1694 | V7: =IF(ISNUMBER(SalesData[[#This Row],[Order Date]]),DATE(YEAR(SalesData[[#This Row],[Order Date]]),DAY(SalesData[[#This Row],[Order Date]]),MONTH(SalesData[[#This Row],[Order Date]])),DATE(VALUE(RIGHT(SalesData[[#This Row],[Order Date]],4)),VALUE(LEFT(SalesData[[#This Row],[Order Date]],FIND("/",SalesData[[#This Row],[Order Date]])-1)),VALUE(MID(SalesData[[#This Row],[Order Date]],FIND("/",SalesData[[#This Row],[Order Date]])+1,FIND("/",SalesData[[#This Row],[Order Date]],FIND("/",SalesData[[#This Row],[Order Date]])+1)-FIND("/",SalesData[[#This Row],[Order Date]])-1)))) -> 41799
A8: 7 | B8: CA-2014-115812 | C8: 41888 | D8: 6/14/2014 | E8: Standard Class | F8: BH-11710 | G8: Brosina Hoffman | H8: Consumer | I8: United States | J8: Los Angeles | K8: California | L8: 90032 | M8: West | N8: OFF-AR-10002833 | O8: Office Supplies | P8: Art | Q8: Newell 322 | R8: 7.28 | S8: 4 | T8: 0 | U8: 1.9656 | V8: =IF(ISNUMBER(SalesData[[#This Row],[Order Date]]),DATE(YEAR(SalesData[[#This Row],[Order Date]]),DAY(SalesData[[#This Row],[Order Date]]),MONTH(SalesData[[#This Row],[Order Date]])),DATE(VALUE(RIGHT(SalesData[[#This Row],[Order Date]],4)),VALUE(LEFT(SalesData[[#This Row],[Order Date]],FIND("/",SalesData[[#This Row],[Order Date]])-1)),VALUE(MID(SalesData[[#This Row],[Order Date]],FIND("/",SalesData[[#This Row],[Order Date]])+1,FIND("/",SalesData[[#This Row],[Order Date]],FIND("/",SalesData[[#This Row],[Order Date]])+1)-FIND("/",SalesData[[#This Row],[Order Date]])-1)))) -> 41799
A9: 8 | B9: CA-2014-115812 | C9: 41888 | D9: 6/14/2014 | E9: Standard Class | F9: BH-11710 | G9: Brosina Hoffman | H9: Consumer | I9: United States | J9: Los Angeles | K9: California | L9: 90032 | M9: West | N9: TEC-PH-10002275 | O9: Technology | P9: Phones | Q9: Mitel 5320 IP Phone VoIP phone | R9: 907.152 | S9: 6 | T9: 0.2 | U9: 90.7152 | V9: =IF(ISNUMBER(SalesData[[#This Row],[Order Date]]),DATE(YEAR(SalesData[[#This Row],[Order Date]]),DAY(SalesData[[#This Row],[Order Date]]),MONTH(SalesData[[#This Row],[Order Date]])),DATE(VALUE(RIGHT(SalesData[[#This Row],[Order Date]],4)),VALUE(LEFT(SalesData[[#This Row],[Order Date]],FIND("/",SalesData[[#This Row],[Order Date]])-1)),VALUE(MID(SalesData[[#This Row],[Order Date]],FIND("/",SalesData[[#This Row],[Order Date]])+1,FIND("/",SalesData[[#This Row],[Order Date]],FIND("/",SalesData[[#This Row],[Order Date]])+1)-FIND("/",SalesData[[#This Row],[Order Date]])-1)))) -> 41799
A10: 9 | B10: CA-2014-115812 | C10: 41888 | D10: 6/14/2014 | E10: Standard Class | F10: BH-11710 | G10: Brosina Hoffman | H10: Consumer | I10: United States | J10: Los Angeles | K10: California | L10: 90032 | M10: West | N10: OFF-BI-10003910 | O10: Office Supplies | P10: Binders | Q10: DXL Angle-View Binders with Locking Rings by Samsill | R10: 18.504 | S10: 3 | T10: 0.2 | U10: 5.7825 | V10: =IF(ISNUMBER(SalesData[[#This Row],[Order Date]]),DATE(YEAR(SalesData[[#This Row],[Order Date]]),DAY(SalesData[[#This Row],[Order Date]]),MONTH(SalesData[[#This Row],[Order Date]])),DATE(VALUE(RIGHT(SalesData[[#This Row],[Order Date]],4)),VALUE(LEFT(SalesData[[#This Row],[Order Date]],FIND("/",SalesData[[#This Row],[Order Date]])-1)),VALUE(MID(SalesData[[#This Row],[Order Date]],FIND("/",SalesData[[#This Row],[Order Date]])+1,FIND("/",SalesData[[#This Row],[Order Date]],FIND("/",SalesData[[#This Row],[Order Date]])+1)-FIND("/",SalesData[[#This Row],[Order Date]])-1)))) -> 41799
A11: 10 | B11: CA-2014-115812 | C11: 41888 | D11: 6/14/2014 | E11: Standard Class | F11: BH-11710 | G11: Brosina Hoffman | H11: Consumer | I11: United States | J11: Los Angeles | K11: California | L11: 90032 | M11: West | N11: OFF-AP-10002892 | O11: Office Supplies | P11: Appliances | Q11: Belkin F5C206VTEL 6 Outlet Surge | R11: 114.9 | S11: 5 | T11: 0 | U11: 34.47 | V11: =IF(ISNUMBER(SalesData[[#This Row],[Order Date]]),DATE(YEAR(SalesData[[#This Row],[Order Date]]),DAY(SalesData[[#This Row],[Order Date]]),MONTH(SalesData[[#This Row],[Order Date]])),DATE(VALUE(RIGHT(SalesData[[#This Row],[Order Date]],4)),VALUE(LEFT(SalesData[[#This Row],[Order Date]],FIND("/",SalesData[[#This Row],[Order Date]])-1)),VALUE(MID(SalesData[[#This Row],[Order Date]],FIND("/",SalesData[[#This Row],[Order Date]])+1,FIND("/",SalesData[[#This Row],[Order Date]],FIND("/",SalesData[[#This Row],[Order Date]])+1)-FIND("/",SalesData[[#This Row],[Order Date]])-1)))) -> 41799
A12: 11 | B12: CA-2014-115812 | C12: 41888 | D12: 6/14/2014 | E12: Standard Class | F12: BH-11710 | G12: Brosina Hoffman | H12: Consumer | I12: United States | J12: Los Angeles | K12: California | L12: 90032 | M12: West | N12: FUR-TA-10001539 | O12: Furniture | P12: Tables | Q12: Chromcraft Rectangular Conference Tables | R12: 1706.184 | S12: 9 | T12: 0.2 | U12: 85.3092 | V12: =IF(ISNUMBER(SalesData[[#This Row],[Order Date]]),DATE(YEAR(SalesData[[#This Row],[Order Date]]),DAY(SalesData[[#This Row],[Order Date]]),MONTH(SalesData[[#This Row],[Order Date]])),DATE(VALUE(RIGHT(SalesData[[#This Row],[Order Date]],4)),VALUE(LEFT(SalesData[[#This Row],[Order Date]],FIND("/",SalesData[[#This Row],[Order Date]])-1)),VALUE(MID(SalesData[[#This Row],[Order Date]],FIND("/",SalesData[[#This Row],[Order Date]])+1,FIND("/",SalesData[[#This Row],[Order Date]],FIND("/",SalesData[[#This Row],[Order Date]])+1)-FIND("/",SalesData[[#This Row],[Order Date]])-1)))) -> 41799
A13: 12 | B13: CA-2014-115812 | C13: 41888 | D13: 6/14/2014 | E13: Standard Class | F13: BH-11710 | G13: Brosina Hoffman | H13: Consumer | I13: United States | J13: Los Angeles | K13: California | L13: 90032 | M13: West | N13: TEC-PH-10002033 | O13: Technology | P13: Phones | Q13: Konftel 250 Conference phone - Charcoal black | R13: 911.424 | S13: 4 | T13: 0.2 | U13: 68.3568 | V13: =IF(ISNUMBER(SalesData[[#This Row],[Order Date]]),DATE(YEAR(SalesData[[#This Row],[Order Date]]),DAY(SalesData[[#This Row],[Order Date]]),MONTH(SalesData[[#This Row],[Order Date]])),DATE(VALUE(RIGHT(SalesData[[#This Row],[Order Date]],4)),VALUE(LEFT(SalesData[[#This Row],[Order Date]],FIND("/",SalesData[[#This Row],[Order Date]])-1)),VALUE(MID(SalesData[[#This Row],[Order Date]],FIND("/",SalesData[[#This Row],[Order Date]])+1,FIND("/",SalesData[[#This Row],[Order Date]],FIND("/",SalesData[[#This Row],[Order Date]])+1)-FIND("/",SalesData[[#This Row],[Order Date]])-1)))) -> 41799
A14: 13 | B14: CA-2017-114412 | C14: 4/15/2017 | D14: 4/20/2017 | E14: Standard Class | F14: AA-10480 | G14: Andrew Allen | H14: Consumer | I14: United States | J14: Concord | K14: North Carolina | L14: 28027 | M14: South | N14: OFF-PA-10002365 | O14: Office Supplies | P14: Paper | Q14: Xerox 1967 | R14: 15.552 | S14: 3 | T14: 0.2 | U14: 5.4432 | V14: =IF(ISNUMBER(SalesData[[#This Row],[Order Date]]),DATE(YEAR(SalesData[[#This Row],[Order Date]]),DAY(SalesData[[#This Row],[Order Date]]),MONTH(SalesData[[#This Row],[Order Date]])),DATE(VALUE(RIGHT(SalesData[[#This Row],[Order Date]],4)),VALUE(LEFT(SalesData[[#This Row],[Order Date]],FIND("/",SalesData[[#This Row],[Order Date]])-1)),VALUE(MID(SalesData[[#This Row],[Order Date]],FIND("/",SalesData[[#This Row],[Order Date]])+1,FIND("/",SalesData[[#This Row],[Order Date]],FIND("/",SalesData[[#This Row],[Order Date]])+1)-FIND("/",SalesData[[#This Row],[Order Date]])-1)))) -> 42840
A15: 14 | B15: CA-2016-161389 | C15: 42502 | D15: 42655 | E15: Standard Class | F15: IM-15070 | G15: Irene Maddox | H15: Consumer | I15: United States | J15: Seattle | K15: Washington | L15: 98103 | M15: West | N15: OFF-BI-10003656 | O15: Office Supplies | P15: Binders | Q15: Fellowes PB200 Plastic Comb Binding Machine | R15: 407.976 | S15: 3 | T15: 0.2 | U15: 132.5922 | V15: =IF(ISNUMBER(SalesData[[#This Row],[Order Date]]),DATE(YEAR(SalesData[[#This Row],[Order Date]]),DAY(SalesData[[#This Row],[Order Date]]),MONTH(SalesData[[#This Row],[Order Date]])),DATE(VALUE(RIGHT(SalesData[[#This Row],[Order Date]],4)),VALUE(LEFT(SalesData[[#This Row],[Order Date]],FIND("/",SalesData[[#This Row],[Order Date]])-1)),VALUE(MID(SalesData[[#This Row],[Order Date]],FIND("/",SalesData[[#This Row],[Order Date]])+1,FIND("/",SalesData[[#This Row],[Order Date]],FIND("/",SalesData[[#This Row],[Order Date]])+1)-FIND("/",SalesData[[#This Row],[Order Date]])-1)))) -> 42709
A16: 15 | B16: US-2015-118983 | C16: 11/22/2015 | D16: 11/26/2015 | E16: Standard Class | F16: HP-14815 | G16: Harold Pawlan | H16: Home Office | I16: United States | J16: Fort Worth | K16: Texas | L16: 76106 | M16: Central | N16: OFF-AP-10002311 | O16: Office Supplies | P16: Appliances | Q16: Holmes Replacement Filter for HEPA Air Cleaner, Very Large Room, HEPA Filter | R16: 68.81 | S16: 5 | T16: 0.8 | U16: -123.858 | V16: =IF(ISNUMBER(SalesData[[#This Row],[Order Date]]),DATE(YEAR(SalesData[[#This Row],[Order Date]]),DAY(SalesData[[#This Row],[Order Date]]),MONTH(SalesData[[#This Row],[Order Date]])),DATE(VALUE(RIGHT(SalesData[[#This Row],[Order Date]],4)),VALUE(LEFT(SalesData[[#This Row],[Order Date]],FIND("/",SalesData[[#This Row],[Order Date]])-1)),VALUE(MID(SalesData[[#This Row],[Order Date]],FIND("/",SalesData[[#This Row],[Order Date]])+1,FIND("/",SalesData[[#This Row],[Order Date]],FIND("/",SalesData[[#This Row],[Order Date]])+1)-FIND("/",SalesData[[#This Row],[Order Date]])-1)))) -> 42330
A17: 16 | B17: US-2015-118983 | C17: 11/22/2015 | D17: 11/26/2015 | E17: Standard Class | F17: HP-14815 | G17: Harold Pawlan | H17: Home Office | I17: United States | J17: Fort Worth | K17: Texas | L17: 76106 | M17: Central | N17: OFF-BI-10000756 | O17: Office Supplies | P17: Binders | Q17: Storex DuraTech Recycled Plastic Frosted Binders | R17: 2.544 | S17: 3 | T17: 0.8 | U17: -3.816 | V17: =IF(ISNUMBER(SalesData[[#This Row],[Order Date]]),DATE(YEAR(SalesData[[#This Row],[Order Date]]),DAY(SalesData[[#This Row],[Order Date]]),MONTH(SalesData[[#This Row],[Order Date]])),DATE(VALUE(RIGHT(SalesData[[#This Row],[Order Date]],4)),VALUE(LEFT(SalesData[[#This Row],[Order Date]],FIND("/",SalesData[[#This Row],[Order Date]])-1)),VALUE(MID(SalesData[[#This Row],[Order Date]],FIND("/",SalesData[[#This Row],[Order Date]])+1,FIND("/",SalesData[[#This Row],[Order Date]],FIND("/",SalesData[[#This Row],[Order Date]])+1)-FIND("/",SalesData[[#This Row],[Order Date]])-1)))) -> 42330
A18: 17 | B18: CA-2014-105893 | C18: 41954 | D18: 11/18/2014 | E18: Standard Class | F18: PK-19075 | G18: Pete Kriz | H18: Consumer | I18: United States | J18: Madison | K18: Wisconsin | L18: 53711 | M18: Central | N18: OFF-ST-10004186 | O18: Office Supplies | P18: Storage | Q18: Stur-D-Stor Shelving, Vertical 5-Shelf: 72"H x 36"W x 18 1/2"D | R18: 665.88 | S18: 6 | T18: 0 | U18: 13.3176 | V18: =IF(ISNUMBER(SalesData[[#This Row],[Order Date]]),DATE(YEAR(SalesData[[#This Row],[Order Date]]),DAY(SalesData[[#This Row],[Order Date]]),MONTH(SalesData[[#This Row],[Order Date]])),DATE(VALUE(RIGHT(SalesData[[#This Row],[Order Date]],4)),VALUE(LEFT(SalesData[[#This Row],[Order Date]],FIND("/",SalesData[[#This Row],[Order Date]])-1)),VALUE(MID(SalesData[[#This Row],[Order Date]],FIND("/",SalesData[[#This Row],[Order Date]])+1,FIND("/",SalesData[[#This Row],[Order Date]],FIND("/",SalesData[[#This Row],[Order Date]])+1)-FIND("/",SalesData[[#This Row],[Order Date]])-1)))) -> 41954
A19: 18 | B19: CA-2014-167164 | C19: 5/13/2014 | D19: 5/15/2014 | E19: Second Class | F19: AG-10270 | G19: Alejandro Grove | H19: Consumer | I19: United States | J19: West Jordan | K19: Utah | L19: 84084 | M19: West | N19: OFF-ST-10000107 | O19: Office Supplies | P19: Storage | Q19: Fellowes Super Stor/Drawer | R19: 55.5 | S19: 2 | T19: 0 | U19: 9.99 | V19: =IF(ISNUMBER(SalesData[[#This Row],[Order Date]]),DATE(YEAR(SalesData[[#This Row],[Order Date]]),DAY(SalesData[[#This Row],[Order Date]]),MONTH(SalesData[[#This Row],[Order Date]])),DATE(VALUE(RIGHT(SalesData[[#This Row],[Order Date]],4)),VALUE(LEFT(SalesData[[#This Row],[Order Date]],FIND("/",SalesData[[#This Row],[Order Date]])-1)),VALUE(MID(SalesData[[#This Row],[Order Date]],FIND("/",SalesData[[#This Row],[Order Date]])+1,FIND("/",SalesData[[#This Row],[Order Date]],FIND("/",SalesData[[#This Row],[Order Date]])+1)-FIND("/",SalesData[[#This Row],[Order Date]])-1)))) -> 41772
A20: 19 | B20: CA-2014-143336 | C20: 8/27/2014 | D20: 41648 | E20: Second Class | F20: ZD-21925 | G20: Zuschuss Donatelli | H20: Consumer | I20: United States | J20: San Francisco | K20: California | L20: 94109 | M20: West | N20: OFF-AR-10003056 | O20: Office Supplies | P20: Art | Q20: Newell 341 | R20: 8.56 | S20: 2 | T20: 0 | U20: 2.4824 | V20: =IF(ISNUMBER(SalesData[[#This Row],[Order Date]]),DATE(YEAR(SalesData[[#This Row],[Order Date]]),DAY(SalesData[[#This Row],[Order Date]]),MONTH(SalesData[[#This Row],[Order Date]])),DATE(VALUE(RIGHT(SalesData[[#This Row],[Order Date]],4)),VALUE(LEFT(SalesData[[#This Row],[Order Date]],FIND("/",SalesData[[#This Row],[Order Date]])-1)),VALUE(MID(SalesData[[#This Row],[Order Date]],FIND("/",SalesData[[#This Row],[Order Date]])+1,FIND("/",SalesData[[#This Row],[Order Date]],FIND("/",SalesData[[#This Row],[Order Date]])+1)-FIND("/",SalesData[[#This Row],[Order Date]])-1)))) -> 41878
A21: 20 | B21: CA-2014-143336 | C21: 8/27/2014 | D21: 41648 | E21: Second Class | F21: ZD-21925 | G21: Zuschuss Donatelli | H21: Consumer | I21: United States | J21: San Francisco | K21: California | L21: 94109 | M21: West | N21: TEC-PH-10001949 | O21: Technology | P21: Phones | Q21: Cisco SPA 501G IP Phone | R21: 213.48 | S21: 3 | T21: 0.2 | U21: 16.011 | V21: =IF(ISNUMBER(SalesData[[#This Row],[Order Date]]),DATE(YEAR(SalesData[[#This Row],[Order Date]]),DAY(SalesData[[#This Row],[Order Date]]),MONTH(SalesData[[#This Row],[Order Date]])),DATE(VALUE(RIGHT(SalesData[[#This Row],[Order Date]],4)),VALUE(LEFT(SalesData[[#This Row],[Order Date]],FIND("/",SalesData[[#This Row],[Order Date]])-1)),VALUE(MID(SalesData[[#This Row],[Order Date]],FIND("/",SalesData[[#This Row],[Order Date]])+1,FIND("/",SalesData[[#This Row],[Order Date]],FIND("/",SalesData[[#This Row],[Order Date]])+1)-FIND("/",SalesData[[#This Row],[Order Date]])-1)))) -> 41878
A22: 21 | B22: CA-2014-143336 | C22: 8/27/2014 | D22: 41648 | E22: Second Class | F22: ZD-21925 | G22: Zuschuss Donatelli | H22: Consumer | I22: United States | J22: San Francisco | K22: California | L22: 94109 | M22: West | N22: OFF-BI-10002215 | O22: Office Supplies | P22: Binders | Q22: Wilson Jones Hanging View Binder, White, 1" | R22: 22.72 | S22: 4 | T22: 0.2 | U22: 7.384 | V22: =IF(ISNUMBER(SalesData[[#This Row],[Order Date]]),DATE(YEAR(SalesData[[#This Row],[Order Date]]),DAY(SalesData[[#This Row],[Order Date]]),MONTH(SalesData[[#This Row],[Order Date]])),DATE(VALUE(RIGHT(SalesData[[#This Row],[Order Date]],4)),VALUE(LEFT(SalesData[[#This Row],[Order Date]],FIND("/",SalesData[[#This Row],[Order Date]])-1)),VALUE(MID(SalesData[[#This Row],[Order Date]],FIND("/",SalesData[[#This Row],[Order Date]])+1,FIND("/",SalesData[[#This Row],[Order Date]],FIND("/",SalesData[[#This Row],[Order Date]])+1)-FIND("/",SalesData[[#This Row],[Order Date]])-1)))) -> 41878
A23: 22 | B23: CA-2016-137330 | C23: 42625 | D23: 12/13/2016 | E23: Standard Class | F23: KB-16585 | G23: Ken Black | H23: Corporate | I23: United States | J23: Fremont | K23: Nebraska | L23: 68025 | M23: Central | N23: OFF-AR-10000246 | O23: Office Supplies | P23: Art | Q23: Newell 318 | R23: 19.46 | S23: 7 | T23: 0 | U23: 5.0596 | V23: =IF(ISNUMBER(SalesData[[#This Row],[Order Date]]),DATE(YEAR(SalesData[[#This Row],[Order Date]]),DAY(SalesData[[#This Row],[Order Date]]),MONTH(SalesData[[#This Row],[Order Date]])),DATE(VALUE(RIGHT(SalesData[[#This Row],[Order Date]],4)),VALUE(LEFT(SalesData[[#This Row],[Order Date]],FIND("/",SalesData[[#This Row],[Order Date]])-1)),VALUE(MID(SalesData[[#This Row],[Order Date]],FIND("/",SalesData[[#This Row],[Order Date]])+1,FIND("/",SalesData[[#This Row],[Order Date]],FIND("/",SalesData[[#This Row],[Order Date]])+1)-FIND("/",SalesData[[#This Row],[Order Date]])-1)))) -> 42713
A24: 23 | B24: CA-2016-137330 | C24: 42625 | D24: 12/13/2016 | E24: Standard Class | F24: KB-16585 | G24: Ken Black | H24: Corporate | I24: United States | J24: Fremont | K24: Nebraska | L24: 68025 | M24: Central | N24: OFF-AP-10001492 | O24: Office Supplies | P24: Appliances | Q24: Acco Six-Outlet Power Strip, 4' Cord Length | R24: 60.34 | S24: 7 | T24: 0 | U24: 15.6884 | V24: =IF(ISNUMBER(SalesData[[#This Row],[Order Date]]),DATE(YEAR(SalesData[[#This Row],[Order Date]]),DAY(SalesData[[#This Row],[Order Date]]),MONTH(SalesData[[#This Row],[Order Date]])),DATE(VALUE(RIGHT(SalesData[[#This Row],[Order Date]],4)),VALUE(LEFT(SalesData[[#This Row],[Order Date]],FIND("/",SalesData[[#This Row],[Order Date]])-1)),VALUE(MID(SalesData[[#This Row],[Order Date]],FIND("/",SalesData[[#This Row],[Order Date]])+1,FIND("/",SalesData[[#This Row],[Order Date]],FIND("/",SalesData[[#This Row],[Order Date]])+1)-FIND("/",SalesData[[#This Row],[Order Date]])-1)))) -> 42713
A25: 24 | B25: US-2017-156909 | C25: 7/16/2017 | D25: 7/18/2017 | E25: Second Class | F25: SF-20065 | G25: Sandra Flanagan | H25: Consumer | I25: United States | J25: Philadelphia | K25: Pennsylvania | L25: 19140 | M25: East | N25: FUR-CH-10002774 | O25: Furniture | P25: Chairs | Q25: Global Deluxe Stacking Chair, Gray | R25: 71.372 | S25: 2 | T25: 0.3 | U25: -1.0196 | V25: =IF(ISNUMBER(SalesData[[#This Row],[Order Date]]),DATE(YEAR(SalesData[[#This Row],[Order Date]]),DAY(SalesData[[#This Row],[Order Date]]),MONTH(SalesData[[#This Row],[Order Date]])),DATE(VALUE(RIGHT(SalesData[[#This Row],[Order Date]],4)),VALUE(LEFT(SalesData[[#This Row],[Order Date]],FIND("/",SalesData[[#This Row],[Order Date]])-1)),VALUE(MID(SalesData[[#This Row],[Order Date]],FIND("/",SalesData[[#This Row],[Order Date]])+1,FIND("/",SalesData[[#This Row],[Order Date]],FIND("/",SalesData[[#This Row],[Order Date]])+1)-FIND("/",SalesData[[#This Row],[Order Date]])-1)))) -> 42932
A26: 25 | B26: CA-2015-106320 | C26: 9/25/2015 | D26: 9/30/2015 | E26: Standard Class | F26: EB-13870 | G26: Emily Burns | H26: Consumer | I26: United States | J26: Orem | K26: Utah | L26: 84057 | M26: West | N26: FUR-TA-10000577 | O26: Furniture | P26: Tables | Q26: Bretford CR4500 Series Slim Rectangular Table | R26: 1044.63 | S26: 3 | T26: 0 | U26: 240.2649 | V26: =IF(ISNUMBER(SalesData[[#This Row],[Order Date]]),DATE(YEAR(SalesData[[#This Row],[Order Date]]),DAY(SalesData[[#This Row],[Order Date]]),MONTH(SalesData[[#This Row],[Order Date]])),DATE(VALUE(RIGHT(SalesData[[#This Row],[Order Date]],4)),VALUE(LEFT(SalesData[[#This Row],[Order Date]],FIND("/",SalesData[[#This Row],[Order Date]])-1)),VALUE(MID(SalesData[[#This Row],[Order Date]],FIND("/",SalesData[[#This Row],[Order Date]])+1,FIND("/",SalesData[[#This Row],[Order Date]],FIND("/",SalesData[[#This Row],[Order Date]])+1)-FIND("/",SalesData[[#This Row],[Order Date]])-1)))) -> 42272
A27: 26 | B27: CA-2016-121755 | C27: 1/16/2016 | D27: 1/20/2016 | E27: Second Class | F27: EH-13945 | G27: Eric Hoffmann | H27: Consumer | I27: United States | J27: Los Angeles | K27: California | L27: 90049 | M27: West | N27: OFF-BI-10001634 | O27: Office Supplies | P27: Binders | Q27: Wilson Jones Active Use Binders | R27: 11.648 | S27: 2 | T27: 0.2 | U27: 4.2224 | V27: =IF(ISNUMBER(SalesData[[#This Row],[Order Date]]),DATE(YEAR(SalesData[[#This Row],[Order Date]]),DAY(SalesData[[#This Row],[Order Date]]),MONTH(SalesData[[#This Row],[Order Date]])),DATE(VALUE(RIGHT(SalesData[[#This Row],[Order Date]],4)),VALUE(LEFT(SalesData[[#This Row],[Order Date]],FIND("/",SalesData[[#This Row],[Order Date]])-1)),VALUE(MID(SalesData[[#This Row],[Order Date]],FIND("/",SalesData[[#This Row],[Order Date]])+1,FIND("/",SalesData[[#This Row],[Order Date]],FIND("/",SalesData[[#This Row],[Order Date]])+1)-FIND("/",SalesData[[#This Row],[Order Date]])-1)))) -> 42385
A28: 27 | B28: CA-2016-121755 | C28: 1/16/2016 | D28: 1/20/2016 | E28: Second Class | F28: EH-13945 | G28: Eric Hoffmann | H28: Consumer | I28: United States | J28: Los Angeles | K28: California | L28: 90049 | M28: West | N28: TEC-AC-10003027 | O28: Technology | P28: Accessories | Q28: Imation 8GB Mini TravelDrive USB 2.0 Flash Drive | R28: 90.57 | S28: 3 | T28: 0 | U28: 11.7741 | V28: =IF(ISNUMBER(SalesData[[#This Row],[Order Date]]),DATE(YEAR(SalesData[[#This Row],[Order Date]]),DAY(SalesData[[#This Row],[Order Date]]),MONTH(SalesData[[#This Row],[Order Date]])),DATE(VALUE(RIGHT(SalesData[[#This Row],[Order Date]],4)),VALUE(LEFT(SalesData[[#This Row],[Order Date]],FIND("/",SalesData[[#This Row],[Order Date]])-1)),VALUE(MID(SalesData[[#This Row],[Order Date]],FIND("/",SalesData[[#This Row],[Order Date]])+1,FIND("/",SalesData[[#This Row],[Order Date]],FIND("/",SalesData[[#This Row],[Order Date]])+1)-FIND("/",SalesData[[#This Row],[Order Date]])-1)))) -> 42385
A29: 28 | B29: US-2015-150630 | C29: 9/17/2015 | D29: 9/21/2015 | E29: Standard Class | F29: TB-21520 | G29: Tracy Blumstein | H29: Consumer | I29: United States | J29: Philadelphia | K29: Pennsylvania | L29: 19140 | M29: East | N29: FUR-BO-10004834 | O29: Furniture | P29: Bookcases | Q29: Riverside Palais Royal Lawyers Bookcase, Royale Cherry Finish | R29: 3083.43 | S29: 7 | T29: 0.5 | U29: -1665.0522 | V29: =IF(ISNUMBER(SalesData[[#This Row],[Order Date]]),DATE(YEAR(SalesData[[#This Row],[Order Date]]),DAY(SalesData[[#This Row],[Order Date]]),MONTH(SalesData[[#This Row],[Order Date]])),DATE(VALUE(RIGHT(SalesData[[#This Row],[Order Date]],4)),VALUE(LEFT(SalesData[[#This Row],[Order Date]],FIND("/",SalesData[[#This Row],[Order Date]])-1)),VALUE(MID(SalesData[[#This Row],[Order Date]],FIND("/",SalesData[[#This Row],[Order Date]])+1,FIND("/",SalesData[[#This Row],[Order Date]],FIND("/",SalesData[[#This Row],[Order Date]])+1)-FIND("/",SalesData[[#This Row],[Order Date]])-1)))) -> 42264
A30: 29 | B30: US-2015-150630 | C30: 9/17/2015 | D30: 9/21/2015 | E30: Standard Class | F30: TB-21520 | G30: Tracy Blumstein | H30: Consumer | I30: United States | J30: Philadelphia | K30: Pennsylvania | L30: 19140 | M30: East | N30: OFF-BI-10000474 | O30: Office Supplies | P30: Binders | Q30: Avery Recycled Flexi-View Covers for Binding Systems | R30: 9.618 | S30: 2 | T30: 0.7 | U30: -7.0532 | V30: =IF(ISNUMBER(SalesData[[#This Row],[Order Date]]),DATE(YEAR(SalesData[[#This Row],[Order Date]]),DAY(SalesData[[#This Row],[Order Date]]),MONTH(SalesData[[#This Row],[Order Date]])),DATE(VALUE(RIGHT(SalesData[[#This Row],[Order Date]],4)),VALUE(LEFT(SalesData[[#This Row],[Order Date]],FIND("/",SalesData[[#This Row],[Order Date]])-1)),VALUE(MID(SalesData[[#This Row],[Order Date]],FIND("/",SalesData[[#This Row],[Order Date]])+1,FIND("/",SalesData[[#This Row],[Order Date]],FIND("/",SalesData[[#This Row],[Order Date]])+1)-FIND("/",SalesData[[#This Row],[Order Date]])-1)))) -> 42264
A31: 30 | B31: US-2015-150630 | C31: 9/17/2015 | D31: 9/21/2015 | E31: Standard Class | F31: TB-21520 | G31: Tracy Blumstein | H31: Consumer | I31: United States | J31: Philadelphia | K31: Pennsylvania | L31: 19140 | M31: East | N31: FUR-FU-10004848 | O31: Furniture | P31: Furnishings | Q31: Howard Miller 13-3/4" Diameter Brushed Chrome Round Wall Clock | R31: 124.2 | S31: 3 | T31: 0.2 | U31: 15.525 | V31: =IF(ISNUMBER(SalesData[[#This Row],[Order Date]]),DATE(YEAR(SalesData[[#This Row],[Order Date]]),DAY(SalesData[[#This Row],[Order Date]]),MONTH(SalesData[[#This Row],[Order Date]])),DATE(VALUE(RIGHT(SalesData[[#This Row],[Order Date]],4)),VALUE(LEFT(SalesData[[#This Row],[Order Date]],FIND("/",SalesData[[#This Row],[Order Date]])-1)),VALUE(MID(SalesData[[#This Row],[Order Date]],FIND("/",SalesData[[#This Row],[Order Date]])+1,FIND("/",SalesData[[#This Row],[Order Date]],FIND("/",SalesData[[#This Row],[Order Date]])+1)-FIND("/",SalesData[[#This Row],[Order Date]])-1)))) -> 42264
A32: 31 | B32: US-2015-150630 | C32: 9/17/2015 | D32: 9/21/2015 | E32: Standard Class | F32: TB-21520 | G32: Tracy Blumstein | H32: Consumer | I32: United States | J32: Philadelphia | K32: Pennsylvania | L32: 19140 | M32: East | N32: OFF-EN-10001509 | O32: Office Supplies | P32: Envelopes | Q32: Poly String Tie Envelopes | R32: 3.264 | S32: 2 | T32: 0.2 | U32: 1.1016 | V32: =IF(ISNUMBER(SalesData[[#This Row],[Order Date]]),DATE(YEAR(SalesData[[#This Row],[Order Date]]),DAY(SalesData[[#This Row],[Order Date]]),MONTH(SalesData[[#This Row],[Order Date]])),DATE(VALUE(RIGHT(SalesData[[#This Row],[Order Date]],4)),VALUE(LEFT(SalesData[[#This Row],[Order Date]],FIND("/",SalesData[[#This Row],[Order Date]])-1)),VALUE(MID(SalesData[[#This Row],[Order Date]],FIND("/",SalesData[[#This Row],[Order Date]])+1,FIND("/",SalesData[[#This Row],[Order Date]],FIND("/",SalesData[[#This Row],[Order Date]])+1)-FIND("/",SalesData[[#This Row],[Order Date]])-1)))) -> 42264
A33: 32 | B33: US-2015-150630 | C33: 9/17/2015 | D33: 9/21/2015 | E33: Standard Class | F33: TB-21520 | G33: Tracy Blumstein | H33: Consumer | I33: United States | J33: Philadelphia | K33: Pennsylvania | L33: 19140 | M33: East | N33: OFF-AR-10004042 | O33: Office Supplies | P33: Art | Q33: BOSTON Model 1800 Electric Pencil Sharpeners, Putty/Woodgrain | R33: 86.304 | S33: 6 | T33: 0.2 | U33: 9.7092 | V33: =IF(ISNUMBER(SalesData[[#This Row],[Order Date]]),DATE(YEAR(SalesData[[#This Row],[Order Date]]),DAY(SalesData[[#This Row],[Order Date]]),MONTH(SalesData[[#This Row],[Order Date]])),DATE(VALUE(RIGHT(SalesData[[#This Row],[Order Date]],4)),VALUE(LEFT(SalesData[[#This Row],[Order Date]],FIND("/",SalesData[[#This Row],[Order Date]])-1)),VALUE(MID(SalesData[[#This Row],[Order Date]],FIND("/",SalesData[[#This Row],[Order Date]])+1,FIND("/",SalesData[[#This Row],[Order Date]],FIND("/",SalesData[[#This Row],[Order Date]])+1)-FIND("/",SalesData[[#This Row],[Order Date]])-1)))) -> 42264
A34: 33 | B34: US-2015-150630 | C34: 9/17/2015 | D34: 9/21/2015 | E34: Standard Class | F34: TB-21520 | G34: Tracy Blumstein | H34: Consumer | I34: United States | J34: Philadelphia | K34: Pennsylvania | L34: 19140 | M34: East | N34: OFF-BI-10001525 | O34: Office Supplies | P34: Binders | Q34: Acco Pressboard Covers with Storage Hooks, 14 7/8" x 11", Executive Red | R34: 6.858 | S34: 6 | T34: 0.7 | U34: -5.715 | V34: =IF(ISNUMBER(SalesData[[#This Row],[Order Date]]),DATE(YEAR(SalesData[[#This Row],[Order Date]]),DAY(SalesData[[#This Row],[Order Date]]),MONTH(SalesData[[#This Row],[Order Date]])),DATE(VALUE(RIGHT(SalesData[[#This Row],[Order Date]],4)),VALUE(LEFT(SalesData[[#This Row],[Order Date]],FIND("/",SalesData[[#This Row],[Order Date]])-1)),VALUE(MID(SalesData[[#This Row],[Order Date]],FIND("/",SalesData[[#This Row],[Order Date]])+1,FIND("/",SalesData[[#This Row],[Order Date]],FIND("/",SalesData[[#This Row],[Order Date]])+1)-FIND("/",SalesData[[#This Row],[Order Date]])-1)))) -> 42264
A35: 34 | B35: US-2015-150630 | C35: 9/17/2015 | D35: 9/21/2015 | E35: Standard Class | F35: TB-21520 | G35: Tracy Blumstein | H35: Consumer | I35: United States | J35: Philadelphia | K35: Pennsylvania | L35: 19140 | M35: East | N35: OFF-AR-10001683 | O35: Office Supplies | P35: Art | Q35: Lumber Crayons | R35: 15.76 | S35: 2 | T35: 0.2 | U35: 3.546 | V35: =IF(ISNUMBER(SalesData[[#This Row],[Order Date]]),DATE(YEAR(SalesData[[#This Row],[Order Date]]),DAY(SalesData[[#This Row],[Order Date]]),MONTH(SalesData[[#This Row],[Order Date]])),DATE(VALUE(RIGHT(SalesData[[#This Row],[Order Date]],4)),VALUE(LEFT(SalesData[[#This Row],[Order Date]],FIND("/",SalesData[[#This Row],[Order Date]])-1)),VALUE(MID(SalesData[[#This Row],[Order Date]],FIND("/",SalesData[[#This Row],[Order Date]])+1,FIND("/",SalesData[[#This Row],[Order Date]],FIND("/",SalesData[[#This Row],[Order Date]])+1)-FIND("/",SalesData[[#This Row],[Order Date]])-1)))) -> 42264
A36: 35 | B36: CA-2017-107727 | C36: 10/19/2017 | D36: 10/23/2017 | E36: Second Class | F36: MA-17560 | G36: Matt Abelman | H36: Home Office | I36: United States | J36: Houston | K36: Texas | L36: 77095 | M36: Central | N36: OFF-PA-10000249 | O36: Office Supplies | P36: Paper | Q36: Easy-staple paper | R36: 29.472 | S36: 3 | T36: 0.2 | U36: 9.9468 | V36: =IF(ISNUMBER(SalesData[[#This Row],[Order Date]]),DATE(YEAR(SalesData[[#This Row],[Order Date]]),DAY(SalesData[[#This Row],[Order Date]]),MONTH(SalesData[[#This Row],[Order Date]])),DATE(VALUE(RIGHT(SalesData[[#This Row],[Order Date]],4)),VALUE(LEFT(SalesData[[#This Row],[Order Date]],FIND("/",SalesData[[#This Row],[Order Date]])-1)),VALUE(MID(SalesData[[#This Row],[Order Date]],FIND("/",SalesData[[#This Row],[Order Date]])+1,FIND("/",SalesData[[#This Row],[Order Date]],FIND("/",SalesData[[#This Row],[Order Date]])+1)-FIND("/",SalesData[[#This Row],[Order Date]])-1)))) -> 43027
A37: 36 | B37: CA-2016-117590 | C37: 42594 | D37: 42655 | E37: First Class | F37: GH-14485 | G37: Gene Hale | H37: Corporate | I37: United States | J37: Richardson | K37: Texas | L37: 75080 | M37: Central | N37: TEC-PH-10004977 | O37: Technology | P37: Phones | Q37: GE 30524EE4 | R37: 1097.544 | S37: 7 | T37: 0.2 | U37: 123.4737 | V37: =IF(ISNUMBER(SalesData[[#This Row],[Order Date]]),DATE(YEAR(SalesData[[#This Row],[Order Date]]),DAY(SalesData[[#This Row],[Order Date]]),MONTH(SalesData[[#This Row],[Order Date]])),DATE(VALUE(RIGHT(SalesData[[#This Row],[Order Date]],4)),VALUE(LEFT(SalesData[[#This Row],[Order Date]],FIND("/",SalesData[[#This Row],[Order Date]])-1)),VALUE(MID(SalesData[[#This Row],[Order Date]],FIND("/",SalesData[[#This Row],[Order Date]])+1,FIND("/",SalesData[[#This Row],[Order Date]],FIND("/",SalesData[[#This Row],[Order Date]])+1)-FIND("/",SalesData[[#This Row],[Order Date]])-1)))) -> 42712
A38: 37 | B38: CA-2016-117590 | C38: 42594 | D38: 42655 | E38: First Class | F38: GH-14485 | G38: Gene Hale | H38: Corporate | I38: United States | J38: Richardson | K38: Texas | L38: 75080 | M38: Central | N38: FUR-FU-10003664 | O38: Furniture | P38: Furnishings | Q38: Electrix Architect's Clamp-On Swing Arm Lamp, Black | R38: 190.92 | S38: 5 | T38: 0.6 | U38: -147.963 | V38: =IF(ISNUMBER(SalesData[[#This Row],[Order Date]]),DATE(YEAR(SalesData[[#This Row],[Order Date]]),DAY(SalesData[[#This Row],[Order Date]]),MONTH(SalesData[[#This Row],[Order Date]])),DATE(VALUE(RIGHT(SalesData[[#This Row],[Order Date]],4)),VALUE(LEFT(SalesData[[#This Row],[Order Date]],FIND("/",SalesData[[#This Row],[Order Date]])-1)),VALUE(MID(SalesData[[#This Row],[Order Date]],FIND("/",SalesData[[#This Row],[Order Date]])+1,FIND("/",SalesData[[#This Row],[Order Date]],FIND("/",SalesData[[#This Row],[Order Date]])+1)-FIND("/",SalesData[[#This Row],[Order Date]])-1)))) -> 42712
A39: 38 | B39: CA-2015-117415 | C39: 12/27/2015 | D39: 12/31/2015 | E39: Standard Class | F39: SN-20710 | G39: Steve Nguyen | H39: Home Office | I39: United States | J39: Houston | K39: Texas | L39: 77041 | M39: Central | N39: OFF-EN-10002986 | O39: Office Supplies | P39: Envelopes | Q39: #10-4 1/8" x 9 1/2" Premium Diagonal Seam Envelopes | R39: 113.328 | S39: 9 | T39: 0.2 | U39: 35.415 | V39: =IF(ISNUMBER(SalesData[[#This Row],[Order Date]]),DATE(YEAR(SalesData[[#This Row],[Order Date]]),DAY(SalesData[[#This Row],[Order Date]]),MONTH(SalesData[[#This Row],[Order Date]])),DATE(VALUE(RIGHT(SalesData[[#This Row],[Order Date]],4)),VALUE(LEFT(SalesData[[#This Row],[Order Date]],FIND("/",SalesData[[#This Row],[Order Date]])-1)),VALUE(MID(SalesData[[#This Row],[Order Date]],FIND("/",SalesData[[#This Row],[Order Date]])+1,FIND("/",SalesData[[#This Row],[Order Date]],FIND("/",SalesData[[#This Row],[Order Date]])+1)-FIND("/",SalesData[[#This Row],[Order Date]])-1)))) -> 42365
A40: 39 | B40: CA-2015-117415 | C40: 12/27/2015 | D40: 12/31/2015 | E40: Standard Class | F40: SN-20710 | G40: Steve Nguyen | H40: Home Office | I40: United States | J40: Houston | K40: Texas | L40: 77041 | M40: Central | N40: FUR-BO-10002545 | O40: Furniture | P40: Bookcases | Q40: Atlantic Metals Mobile 3-Shelf Bookcases, Custom Colors | R40: 532.3992 | S40: 3 | T40: 0.32 | U40: -46.9764 | V40: =IF(ISNUMBER(SalesData[[#This Row],[Order Date]]),DATE(YEAR(SalesData[[#This Row],[Order Date]]),DAY(SalesData[[#This Row],[Order Date]]),MONTH(SalesData[[#This Row],[Order Date]])),DATE(VALUE(RIGHT(SalesData[[#This Row],[Order Date]],4)),VALUE(LEFT(SalesData[[#This Row],[Order Date]],FIND("/",SalesData[[#This Row],[Order Date]])-1)),VALUE(MID(SalesData[[#This Row],[Order Date]],FIND("/",SalesData[[#This Row],[Order Date]])+1,FIND("/",SalesData[[#This Row],[Order Date]],FIND("/",SalesData[[#This Row],[Order Date]])+1)-FIND("/",SalesData[[#This Row],[Order Date]])-1)))) -> 42365
...

Sheet Formulas Demo
A1: Excel Formulas and Functions on Superstore data.
A3: Function | B3: What I am doing | C3: Result | D3: Formula used | E3: When to use it
A4: VLOOKUP | B4: Find the Sales for Row ID 3 | C4: =VLOOKUP(3,SalesData[],18,FALSE) -> 14.62 | D4: =_xlfn.FORMULATEXT(C4) -> =VLOOKUP(3,SalesData,18,FALSE) | E4: Use when the ID is in the first column. It breaks if columns move because it needs a column number.
A5: XLOOKUP | B5: Find the Sales for Row ID 3 | C5: =_xlfn.XLOOKUP(3,SalesData[Row ID],SalesData[Sales]) -> 14.62 | D5: =_xlfn.FORMULATEXT(C5) -> =XLOOKUP(3,SalesData[Row ID],SalesData[Sales]) | E5: Newer and safer than VLOOKUP. No column number needed and it can look in any direction.
A6: INDEX/MATCH | B6: Find the Sales for Row ID 3 | C6: =INDEX(SalesData[Sales],MATCH(3,SalesData[Row ID],0)) -> 14.62 | D6: =_xlfn.FORMULATEXT(C6) -> =INDEX(SalesData[Sales],MATCH(3,SalesData[Row ID],0)) | E6: Use when XLOOKUP is not available or the lookup column is not on the left.
A7: IF | B7: Is the 4th order a profit or a loss | C7: =IF('Raw Data'!U5>0,"Profit","Loss") -> Loss | D7: =_xlfn.FORMULATEXT(C7) -> =IF('Raw Data'!U5>0,"Profit","Loss") | E7: Use for a simple yes or no decision with one condition.
A8: Nested IF | B8: Label the first sale as High, Medium or Low | C8: =IF('Raw Data'!R2>500,"High",IF('Raw Data'!R2>100,"Medium","Low")) -> Medium | D8: =_xlfn.FORMULATEXT(C8) -> =IF('Raw Data'!R2>500,"High",IF('Raw Data'!R2>100,"Medium","Low")) | E8: Use for 3 or more groups. Keep it short because too many IFs are hard to read.
A9: SUMIF | B9: Total sales of the West region | C9: =SUMIF(SalesData[Region],"West",SalesData[Sales]) -> 725457.82 | D9: =_xlfn.FORMULATEXT(C9) -> =SUMIF(SalesData[Region],"West",SalesData[Sales]) | E9: Use to add up values with ONE condition.
A10: SUMIFS | B10: West sales of the Technology category | C10: =SUMIFS(SalesData[Sales],SalesData[Region],"West",SalesData[Category],"Technology") -> 251991.83 | D10: =_xlfn.FORMULATEXT(C10) -> =SUMIFS(SalesData[Sales],SalesData[Region],"West",SalesData[Category],"Technology") | E10: Use to add up values with TWO or more conditions.
A11: COUNTIFS | B11: Count West order lines that made a loss | C11: =COUNTIFS(SalesData[Region],"West",SalesData[Profit],"<0") -> 318 | D11: =_xlfn.FORMULATEXT(C11) -> =COUNTIFS(SalesData[Region],"West",SalesData[Profit],"<0") | E11: Use to count rows that meet one or more conditions.
A12: AVERAGEIFS | B12: Average discount in the Central region | C12: =AVERAGEIFS(SalesData[Discount],SalesData[Region],"Central") -> 0.24035299 | D12: =_xlfn.FORMULATEXT(C12) -> =AVERAGEIFS(SalesData[Discount],SalesData[Region],"Central") | E12: Use to find the average of a group.
A13: UPPER | B13: First customer name in capital letters | C13: =UPPER('Raw Data'!G2) -> CLAIRE GUTE | D13: =_xlfn.FORMULATEXT(C13) -> =UPPER('Raw Data'!G2) | E13: Use to make text consistent in capital letters.
A14: LEFT + FIND | B14: Get the first name of the first customer | C14: =LEFT('Raw Data'!G2,FIND(" ",'Raw Data'!G2)-1) -> Claire | D14: =_xlfn.FORMULATEXT(C14) -> =LEFT('Raw Data'!G2,FIND(" ",'Raw Data'!G2)-1) | E14: Use to cut part of a text, like a first name.
A15: TRIM + PROPER | B15: Clean a messy name with extra spaces | C15: =PROPER(TRIM(" claire gute ")) -> Claire Gute | D15: =_xlfn.FORMULATEXT(C15) -> =PROPER(TRIM(" claire gute ")) | E15: Use to clean messy text with extra spaces and wrong capitals.
A16: CONCAT | B16: Join the Order ID and customer name | C16: =_xlfn.CONCAT('Raw Data'!B2," - ",'Raw Data'!G2) -> CA-2016-152156 - Claire Gute | D16: =_xlfn.FORMULATEXT(C16) -> =CONCAT('Raw Data'!B2," - ",'Raw Data'!G2) | E16: Use to join text from different cells.
A17: LEN | B17: Count the characters in the first customer name | C17: =LEN('Raw Data'!G2) -> 11 | D17: =_xlfn.FORMULATEXT(C17) -> =LEN('Raw Data'!G2) | E17: Use to count characters, for example to check ID lengths.
A18: IFERROR (not found) | B18: Look up a Row ID that does not exist | C18: =IFERROR(VLOOKUP(99999,SalesData[],18,FALSE),"Not found") -> Not found | D18: =_xlfn.FORMULATEXT(C18) -> =IFERROR(VLOOKUP(99999,SalesData,18,FALSE),"Not found") | E18: Use to show a friendly message instead of an error.
A19: Text vs number mismatch | B19: Look up the number 3 typed as text | C19: =IFERROR(VLOOKUP("3",SalesData[],18,FALSE),"Mismatch: text vs number") -> Mismatch: text vs number | D19: =_xlfn.FORMULATEXT(C19) -> =IFERROR(VLOOKUP("3",SalesData,18,FALSE),"Mismatch: text vs number") | E19: A lookup fails when one side is text and the other is a number. Convert one of them so they match.
A20: IF + blank cell | B20: Check an empty cell | C20: =IF(Z1="","Blank cell","Has value") -> Blank cell | D20: =_xlfn.FORMULATEXT(C20) -> =IF(Z1="","Blank cell","Has value") | E20: Use to catch empty cells before they break a calculation.
